Workbook

Sheet Sheet4
A1: Project Name | B1: Tracker Code
A2: Hostel 4 | B2: Track-H4
A3: Desai Sethi School of Entreprenurship new Building | B3: Track-DSSE
A4: NSAC | B4: Track-NSAC
A5: Rahul Bajaj Technology Innovation Centre | B5: Track-RBTIC
A6: A91 Eco Hub | B6: Track-A91
A7: COPT- BETIC | B7: TRACK-COPT
A8: AB1 | B8: Track-AB1
A9: AB2 | B9: Track-AB2
A10: ASB1 | B10: Track-ASB1
A11: ASB2 | B11: Track-ASB2
A12: KV | B12: Track-KV
... A45: HRT | B45: Track-HRT

Sheet Projects Tracker
A1: WBS Code | B1: Project Name | C1: Category | D1: Built-up Area (sq ft) | E1: Start Date | F1: Target Completion | G1: Project Cost | H1: Funds Committed (After Admin Cost) | I1: FUNDS COMMITTED FOR INFRASTRUCTURE | J1: Received Funds | K1: Blocks/Impediments and Redflag | L1: Donor Name | M1: Donor Contact | N1: Progress | O1: Status | P1: No. of Beds/ Occupency, and other details | Q1: Latest Photos Link | R1: Drawings | S1: Reports | T1: Location | U1: % Completion | V1: Floors | Z1: Milestones Sheet | AA1: Floor Plan Sheet | AB1: Last Updated | AC1: Special Features | AG1: Permits | AH1: MOUs
A2: DO/2025-HCT4 | B2: Hostel 4 | C2: Student Housing | D2: 398426 | E2: 2023 | F2: 2025 | G2: 1600000000 | H2: 200000000 | I2: =IF(COUNTIF('N- Finances'!$A:$A,$B2)>1, SUMIFS('N- Finances'!$C:$C,'N- Finances'!$A:$A,$B2), _xlfn.XLOOKUP($B2,'N- Finances'!$A:$A,'N- Finances'!$C:$C,"",0) ) | L2: Multiple | M2: ravi.naware@gmail.com | N2: Completed and Active | O2: Active | Q2: Pictures | R2: Designs | S2: Reports | T2: https://maps.app.goo.gl/ZuiG7MAaST3dvLzv5 | U2: =MAX(0, MIN(1, (TODAY()-E2)/(F2-E2))) -> 1 | AB2: 46034
A3: DO/2021-DSSE | B3: Desai Sethi School of Entreprenurship new Building | C3: Research | D3: 134506 | E3: 2023 | F3: 45870 | H3: 233006082 | I3: 233006082 | L3: Bharat Desai (27Cr) | M3: bdesai.mail@gmail.com | N3: Stage8- Completed | O3: Active | T3: https://maps.app.goo.gl/HQQ5FuNUiyoRAGib6 | U3: =MAX(0, MIN(1, (TODAY()-E3)/(F3-E3))) -> 1 | AB3: 46034
B4: NSAC | C4: Academic | D4: 57242 | E4: 2024 | F4: 46204 | G4: 450000000 | H4: 0 | I4: =IF(COUNTIF('N- Finances'!$A:$A,$B4)>1, SUMIFS('N- Finances'!$C:$C,'N- Finances'!$A:$A,$B4), _xlfn.XLOOKUP($B4,'N- Finances'!$A:$A,'N- Finances'!$C:$C,"",0) ) | L4: open | N4: Completed and Active | O4: Active | U4: =MAX(0, MIN(1, (TODAY()-E4)/(F4-E4))) -> 0.99701222 | AB4: 46034
A5: DO/2019-RBIC | B5: Rahul Bajaj Technology Innovation Centre | D5: 208460 | G5: 700000000 | H5: 250000000 | I5: =IF(COUNTIF('N- Finances'!$A:$A,$B5)>1, SUMIFS('N- Finances'!$C:$C,'N- Finances'!$A:$A,$B5), _xlfn.XLOOKUP($B5,'N- Finances'!$A:$A,'N- Finances'!$C:$C,"",0) ) | L5: Rahul Bajaj | N5: Stage8- Completed | O5: Non-Active | T5: https://maps.app.goo.gl/UitkwUPGkWhabER28 | U5: =MAX(0, MIN(1, (TODAY()-E5)/(F5-E5))) -> #DIV/0! | AB5: 46034
B6: A91 Eco Hub | C6: Research | D6: 54235 | F6: 2024 | G6: 90000000 | H6: 155200000 | I6: =IF(COUNTIF('N- Finances'!$A:$A,$B6)>1, SUMIFS('N- Finances'!$C:$C,'N- Finances'!$A:$A,$B6), _xlfn.XLOOKUP($B6,'N- Finances'!$A:$A,'N- Finances'!$C:$C,"",0) ) -> 100000000 | L6: Abhay Pandey | N6: Completed and Active | O6: Non-Active | U6: =MAX(0, MIN(1, (TODAY()-E6)/(F6-E6))) -> 1 | AB6: 46034
A7: DO/2025-ICICI | B7: COPT- BETIC | C7: Research | D7: 156496 | E7: 2024 | F7: 46296 | G7: 99000000 | H7: 142700000 | I7: =IF(COUNTIF('N- Finances'!$A:$A,$B7)>1, SUMIFS('N- Finances'!$C:$C,'N- Finances'!$A:$A,$B7), _xlfn.XLOOKUP($B7,'N- Finances'!$A:$A,'N- Finances'!$C:$C,"",0) ) | L7: ICICI 14Cr (1/7 of the total project) for BETIC Centre to be hosted | M7: deepak.patil@icicifoundation.org, prashant.deokar@icicifoundation.org | N7: Completed and Active | O7: Active | Q7: Pictures | U7: =MAX(0, MIN(1, (TODAY()-E7)/(F7-E7))) -> 0.99494037 | Z7: 716100000 | AB7: 46034
A8: DO/2024-MOSL | B8: AB1 | C8: Academic | D8: 386209 | E8: 2024 | F8: 46478 | G8: 1900000000 | H8: 997000000 | I8: =IF(COUNTIF('N- Finances'!$A:$A,$B8)>1, SUMIFS('N- Finances'!$C:$C,'N- Finances'!$A:$A,$B8), _xlfn.XLOOKUP($B8,'N- Finances'!$A:$A,'N- Finances'!$C:$C,"",0) ) -> 100000000 | L8: Motilal Oswal (95 Cr), Ashank Desai (ADCPS) (10Cr), Fedex (7.5Cr) CMInDS (Lakhamraju-17.53 Cr, SBI-7.78 Cr, Gupshup-9.76 Cr, Arpit Mathur-5.61Cr, Kashyap & Shruti Deorah-5.61Cr, S. Rizvi- 1.45Cr ) (48 Cr) Steel From JSW (in Kind) | N8: Stage3-Under Construction | O8: Active | Q8: https://iitbacr-my.sharepoint.com/:f:/p/siddhant_gupta/IgCdKabfm-gwQL_3mz1DIDyUASrEZ6YR15bftulpbqYKx1s?e=xwQi8c | R8: Designs | S8: Reports | T8: https://maps.app.goo.gl/sbCM8K2bu5k4Dn4bA | U8: =MAX(0, MIN(1, (TODAY()-E8)/(F8-E8))) -> 0.99086696 | AB8: 46034
A9: DO/2023-FEDX | B9: AB2 | C9: Academic | E9: 2024 | F9: 46478 | H9: 562600000 | I9: =IF(COUNTIF('N- Finances'!$A:$A,$B9)>1, SUMIFS('N- Finances'!$C:$C,'N- Finances'!$A:$A,$B9), _xlfn.XLOOKUP($B9,'N- Finances'!$A:$A,'N- Finances'!$C:$C,"",0) ) -> 487600000 | N9: Stage3-Under Construction | O9: Active | R9: Designs | S9: Reports | T9: https://maps.app.goo.gl/sbCM8K2bu5k4Dn4bA | U9: =MAX(0, MIN(1, (TODAY()-E9)/(F9-E9))) -> 0.99086696 | AB9: 46034
B10: ASB1 | C10: Academic | D10: 353282 | E10: 2024 | F10: 46357 | G10: 2180000000 | H10: 0 | I10: =IF(COUNTIF('N- Finances'!$A:$A,$B10)>1, SUMIFS('N- Finances'!$C:$C,'N- Finances'!$A:$A,$B10), _xlfn.XLOOKUP($B10,'N- Finances'!$A:$A,'N- Finances'!$C:$C,"",0) ) | L10: Wadhwani (60 Cr), Nandan (20 Cr) Koita’s (KCDH) (15 Cr) | N10: Stage3-Under Construction | O10: Active | R10: Designs | S10: Reports | T10: https://maps.app.goo.gl/us2gAFPmcAuwdctYA | U10: =MAX(0, MIN(1, (TODAY()-E10)/(F10-E10))) -> 0.99357138 | AB10: 46034
B11: ASB2 | D11: 115970 | E11: 2024 | F11: 46357 | G11: 900000000 | H11: 1024500000 | I11: =IF(COUNTIF('N- Finances'!$A:$A,$B11)>1, SUMIFS('N- Finances'!$C:$C,'N- Finances'!$A:$A,$B11), _xlfn.XLOOKUP($B11,'N- Finances'!$A:$A,'N- Finances'!$C:$C,"",0) ) -> 150000000 | L11: Wadhwani, Nandan | N11: Stage3-Under Construction | O11: Active | R11: Designs | S11: Reports | T11: https://maps.app.goo.gl/us2gAFPmcAuwdctYA | U11: =MAX(0, MIN(1, (TODAY()-E11)/(F11-E11))) -> 0.99357138 | AB11: 46034
B12: KV | C12: Non-academic | D12: 0 | E12: 2024 | F12: 46357 | G12: 0 | H12: 599480000 | I12: =IF(COUNTIF('N- Finances'!$A:$A,$B12)>1, SUMIFS('N- Finances'!$C:$C,'N- Finances'!$A:$A,$B12), _xlfn.XLOOKUP($B12,'N- Finances'!$A:$A,'N- Finances'!$C:$C,"",0) ) | L12: Prashant Sharma | N12: Stage3-Under Construction | O12: Active | T12: https://maps.app.goo.gl/3Nn1zCEVRv1UzBmSA | U12: =MAX(0, MIN(1, (TODAY()-E12)/(F12-E12))) -> 0.99357138 | AB12: 46034
B13: Faculty Housing | C13: Non-academic | D13: 455452 | G13: 1000000000 | H13: 0 | I13: =IF(COUNTIF('N- Finances'!$A:$A,$B13)>1, SUMIFS('N- Finances'!$C:$C,'N- Finances'!$A:$A,$B13), _xlfn.XLOOKUP($B13,'N- Finances'!$A:$A,'N- Finances'!$C:$C,"",0) ) | L13: Nandan Nilkani (80 Cr) | N13: Stage3-Under Construction | O13: Active | U13: =MAX(0, MIN(1, (TODAY()-E13)/(F13-E13))) -> #DIV/0! | AB13: 46034
B14: Research HUB | C14: Research | D14: 160500 | E14: 2026 | F14: 46722 | G14: 1410000000 | H14: 0 | I14: =IF(COUNTIF('N- Finances'!$A:$A,$B14)>1, SUMIFS('N- Finances'!$C:$C,'N- Finances'!$A:$A,$B14), _xlfn.XLOOKUP($B14,'N- Finances'!$A:$A,'N- Finances'!$C:$C,"",0) ) | L14: Open | N14: Stage2-Design | O14: Active | Q14: Photos | U14: =MAX(0, MIN(1, (TODAY()-E14)/(F14-E14))) -> 0.98545731 | AB14: 46034
A15: DO/2018-MKAC | B15: Alumni centre | C15: Non-academic | D15: 155454 | E15: 2026 | F15: 2028 | G15: 110000000 | H15: 164500000 | I15: =IF(COUNTIF('N- Finances'!$A:$A,$B15)>1, SUMIFS('N- Finances'!$C:$C,'N- Finances'!$A:$A,$B15), _xlfn.XLOOKUP($B15,'N- Finances'!$A:$A,'N- Finances'!$C:$C,"",0) ) -> 100000000 | L15: Mohan Kavrie, Everest (10Cr +7.5+5.42Cr) | N15: Stage2-Design | O15: Active | Q15: Pictures | R15: Designs | S15: Reports | T15: https://maps.app.goo.gl/uhZViCJZzjVEvFzo9 | U15: =MAX(0, MIN(1, (TODAY()-E15)/(F15-E15))) -> 1 | AB15: 46034
B16: AB3 | C16: Academic | D16: 299024 | E16: 2026 | F16: 46722 | G16: 2580000000 | H16: 970000000 | I16: =IF(COUNTIF('N- Finances'!$A:$A,$B16)>1, SUMIFS('N- Finances'!$C:$C,'N- Finances'!$A:$A,$B16), _xlfn.XLOOKUP($B16,'N- Finances'!$A:$A,'N- Finances'!$C:$C,"",0) ) | L16: Anonymous (100 Cr) (AB4) | N16: Stage2-Design | O16: Active | R16: Designs | S16: Reports | T16: https://maps.app.goo.gl/KWuvv22ohWj3c5wp6 | U16: =MAX(0, MIN(1, (TODAY()-E16)/(F16-E16))) -> 0.98545731 | AB16: 46034
B17: AB4 & GESH Building | C17: Academic | E17: 2026 | F17: 46722 | I17: =IF(COUNTIF('N- Finances'!$A:$A,$B17)>1, SUMIFS('N- Finances'!$C:$C,'N- Finances'!$A:$A,$B17), _xlfn.XLOOKUP($B17,'N- Finances'!$A:$A,'N- Finances'!$C:$C,"",0) ) | N17: Stage2-Design | O17: Active | T17: https://maps.app.goo.gl/sbCM8K2bu5k4Dn4bA | U17: =MAX(0, MIN(1, (TODAY()-E17)/(F17-E17))) -> 0.98545731 | AB17: 46034
B18: Efficiency Appt | C18: Non-academic | D18: 502675 | G18: 226000000 | H18: 0 | I18: =IF(COUNTIF('N- Finances'!$A:$A,$B18)>1, SUMIFS('N- Finances'!$C:$C,'N- Finances'!$A:$A,$B18), _xlfn.XLOOKUP($B18,'N- Finances'!$A:$A,'N- Finances'!$C:$C,"",0) ) | L18: Open | N18: Stage2-Design | O18: Active | U18: =MAX(0, MIN(1, (TODAY()-E18)/(F18-E18))) -> #DIV/0! | AB18: 46034
A19: DO/2025-HCT9 | B19: Hostel 9 | C19: Student Housing | D19: 322917 | E19: 46174 | F19: 46813 | G19: 1650000000 | H19: 643293750 | I19: =IF(COUNTIF('N- Finances'!$A:$A,$B19)>1, SUMIFS('N- Finances'!$C:$C,'N- Finances'!$A:$A,$B19), _xlfn.XLOOKUP($B19,'N- Finances'!$A:$A,'N- Finances'!$C:$C,"",0) ) -> 643293750 | L19: Jitendra Mohan & Swapna (64Cr) | M19: bdesai.mail@gmail.com | N19: Stage2-Design | O19: Active | Q19: Pictures | R19: Designs | S19: Reports | T19: https://maps.app.goo.gl/oHAPhofQHPXYwgYm9 | U19: =MAX(0, MIN(1, (TODAY()-E19)/(F19-E19))) -> 0 | AB19: 46034
A20: DO/2024-HCT6 | B20: Hostel 6 | C20: Student Housing | D20: 423022 | E20: 46174 | F20: 46813 | G20: 1800000000 | H20: 1050000000 | I20: =IF(COUNTIF('N- Finances'!$A:$A,$B20)>1, SUMIFS('N- Finances'!$C:$C,'N- Finances'!$A:$A,$B20), _xlfn.XLOOKUP($B20,'N- Finances'!$A:$A,'N- Finances'!$C:$C,"",0) ) | L20: Browserstack, Ritesh & Nakul (90 Cr) | M20: siddharth.l@browserstack.com | N20: Stage1-Planning | O20: Active | Q20: Pictures | R20: Designs | S20: Reports | T20: https://maps.app.goo.gl/tfNCyrwxG1sQgT916 | U20: =MAX(0, MIN(1, (TODAY()-E20)/(F20-E20))) -> 0 | AA20: Floor Plan | AB20: 46034 | AC20: Yoga room, Gymnasium, Dance/music room, Cafeteria/Canteen, Student Lounge | AG20: link
B21: Girls Hostel | C21: Student Housing | D21: 51451 | E21: 45182 | F21: 46277 | G21: 3000000000 | H21: 0 | I21: =IF(COUNTIF('N- Finances'!$A:$A,$B21)>1, SUMIFS('N- Finances'!$C:$C,'N- Finances'!$A:$A,$B21), _xlfn.XLOOKUP($B21,'N- Finances'!$A:$A,'N- Finances'!$C:$C,"",0) ) | L21: Open | N21: Stage1-Planning | O21: Active | U21: =MAX(0, MIN(1, (TODAY()-E21)/(F21-E21))) -> 0.81278539 | AB21: 46034
B22: Lecture Hall Complex (OAT) | C22: Academic | D22: 129898 | G22: 120000000 | H22: 0 | I22: =IF(COUNTIF('N- Finances'!$A:$A,$B22)>1, SUMIFS('N- Finances'!$C:$C,'N- Finances'!$A:$A,$B22), _xlfn.XLOOKUP($B22,'N- Finances'!$A:$A,'N- Finances'!$C:$C,"",0) ) | L22: Open | N22: Stage1-Planning | O22: Active | U22: =MAX(0, MIN(1, (TODAY()-E22)/(F22-E22))) -> #DIV/0! | AB22: 46034
B23: ARL | C23: Academic | D23: 112742 | E23: 2026 | F23: 46600 | G23: 170000000 | H23: 0 | I23: =IF(COUNTIF('N- Finances'!$A:$A,$B23)>1, SUMIFS('N- Finances'!$C:$C,'N- Finances'!$A:$A,$B23), _xlfn.XLOOKUP($B23,'N- Finances'!$A:$A,'N- Finances'!$C:$C,"",0) ) | L23: Open | N23: Stage1-Planning | O23: Active | U23: =MAX(0, MIN(1, (TODAY()-E23)/(F23-E23))) -> 0.98815453 | AB23: 46034
B24: EHV | C24: Non-academic | D24: 38750 | G24: 127000000 | H24: 0 | I24: =IF(COUNTIF('N- Finances'!$A:$A,$B24)>1, SUMIFS('N- Finances'!$C:$C,'N- Finances'!$A:$A,$B24), _xlfn.XLOOKUP($B24,'N- Finances'!$A:$A,'N- Finances'!$C:$C,"",0) ) | L24: Open | N24: Stage1-Planning | O24: Active | U24: =MAX(0, MIN(1, (TODAY()-E24)/(F24-E24))) -> #DIV/0! | AB24: 46034
B25: MLCP | C25: Non-academic | D25: 215200 | G25: 140000000 | H25: 0 | I25: =IF(COUNTIF('N- Finances'!$A:$A,$B25)>1, SUMIFS('N- Finances'!$C:$C,'N- Finances'!$A:$A,$B25), _xlfn.XLOOKUP($B25,'N- Finances'!$A:$A,'N- Finances'!$C:$C,"",0) ) | L25: Open | N25: Stage1-Planning | O25: Active | U25: =MAX(0, MIN(1, (TODAY()-E25)/(F25-E25))) -> #DIV/0! | AB25: 46034
B26: Drone Centre | C26: Academic | D26: 32280 | E26: 2026 | F26: 2027 | G26: 97000000 | H26: 0 | I26: =IF(COUNTIF('N- Finances'!$A:$A,$B26)>1, SUMIFS('N- Finances'!$C:$C,'N- Finances'!$A:$A,$B26), _xlfn.XLOOKUP($B26,'N- Finances'!$A:$A,'N- Finances'!$C:$C,"",0) ) | L26: Open | N26: Stage1-Planning | O26: Active | U26: =MAX(0, MIN(1, (TODAY()-E26)/(F26-E26))) -> 1 | AB26: 46034
B27: Hostel 19 | C27: Student Housing | D27: 360791.52 | E27: 2023 | F27: 45992 | G27: 1000000000 | H27: 0 | I27: =IF(COUNTIF('N- Finances'!$A:$A,$B27)>1, SUMIFS('N- Finances'!$C:$C,'N- Finances'!$A:$A,$B27), _xlfn.XLOOKUP($B27,'N- Finances'!$A:$A,'N- Finances'!$C:$C,"",0) ) | L27: Open | N27: Stage5-Completed | O27: Active
B28: Hostel 11 | C28: Student Housing | D28: 51432.8 | E28: 46357 | F28: 2028 | G28: 1600000000 | H28: 0 | I28: =IF(COUNTIF('N- Finances'!$A:$A,$B28)>1, SUMIFS('N- Finances'!$C:$C,'N- Finances'!$A:$A,$B28), _xlfn.XLOOKUP($B28,'N- Finances'!$A:$A,'N- Finances'!$C:$C,"",0) ) | L28: Open | N28: Stage1-Planning | O28: Active
B29: Gogri Hub | C29: Lab | E29: 45931 | F29: 46023 | G29: 72750000 | H29: 72750000 | I29: =IF(COUNTIF('N- Finances'!$A:$A,$B29)>1, SUMIFS('N- Finances'!$C:$C,'N- Finances'!$A:$A,$B29), _xlfn.XLOOKUP($B29,'N- Finances'!$A:$A,'N- Finances'!$C:$C,"",0) ) | L29: Open | N29: Stage3-Under Construction | O29: Active | Q29: Pictures | U29: =MAX(0, MIN(1, (TODAY()-E29)/(F29-E29))) -> 1
B30: BASKETBALL COURT ARINA-CLASS OF 95 | I30: =IF(COUNTIF('N- Finances'!$A:$A,$B30)>1, SUMIFS('N- Finances'!$C:$C,'N- Finances'!$A:$A,$B30), _xlfn.XLOOKUP($B30,'N- Finances'!$A:$A,'N- Finances'!$C:$C,"",0) ) -> 66000000 | J30: 66000000
B31: NAMING TO CLASS OF 1993 | I31: =IF(COUNTIF('N- Finances'!$A:$A,$B31)>1, SUMIFS('N- Finances'!$C:$C,'N- Finances'!$A:$A,$B31), _xlfn.XLOOKUP($B31,'N- Finances'!$A:$A,'N- Finances'!$C:$C,"",0) ) -> 14000000 | J31: 14000000
B32: SHRIDHAR SHUKLA IITB TRUST LAB | I32: =IF(COUNTIF('N- Finances'!$A:$A,$B32)>1, SUMIFS('N- Finances'!$C:$C,'N- Finances'!$A:$A,$B32), _xlfn.XLOOKUP($B32,'N- Finances'!$A:$A,'N- Finances'!$C:$C,"",0) ) -> 37500000 | J32: 37500000
B33: Naming R.NO.21 VMCC PROF.VASI | I33: =IF(COUNTIF('N- Finances'!$A:$A,$B33)>1, SUMIFS('N- Finances'!$C:$C,'N- Finances'!$A:$A,$B33), _xlfn.XLOOKUP($B33,'N- Finances'!$A:$A,'N- Finances'!$C:$C,"",0) ) -> 9000000 | J33: 9000000
B34: Naming corpus of HE_IITB Y1,Y2 | I34: =IF(COUNTIF('N- Finances'!$A:$A,$B34)>1, SUMIFS('N- Finances'!$C:$C,'N- Finances'!$A:$A,$B34), _xlfn.XLOOKUP($B34,'N- Finances'!$A:$A,'N- Finances'!$C:$C,"",0) ) -> 20000000 | J34: 10800000
B35: INOX | I35: =IF(COUNTIF('N- Finances'!$A:$A,$B35)>1, SUMIFS('N- Finances'!$C:$C,'N- Finances'!$A:$A,$B35), _xlfn.XLOOKUP($B35,'N- Finances'!$A:$A,'N- Finances'!$C:$C,"",0) ) -> 7500000 | J35: 6750000
B36: Kishore Seendripu-Lecture Hall Complex 3 | I36: =IF(COUNTIF('N- Finances'!$A:$A,$B36)>1, SUMIFS('N- Finances'!$C:$C,'N- Finances'!$A:$A,$B36), _xlfn.XLOOKUP($B36,'N- Finances'!$A:$A,'N- Finances'!$C:$C,"",0) ) -> 416450000 | J36: 340700000
B37: EE Dept. 2nd Floor- Arun Firodia | I37: =IF(COUNTIF('N- Finances'!$A:$A,$B37)>1, SUMIFS('N- Finances'!$C:$C,'N- Finances'!$A:$A,$B37), _xlfn.XLOOKUP($B37,'N- Finances'!$A:$A,'N- Finances'!$C:$C,"",0) ) -> 75000000 | J37: 17460000
B38: Citadel Securities | I38: =IF(COUNTIF('N- Finances'!$A:$A,$B38)>1, SUMIFS('N- Finances'!$C:$C,'N- Finances'!$A:$A,$B38), _xlfn.XLOOKUP($B38,'N- Finances'!$A:$A,'N- Finances'!$C:$C,"",0) ) -> 20000000 | J38: 16000000
B39: Surendra & Karen Gupta LT 105 | I39: =IF(COUNTIF('N- Finances'!$A:$A,$B39)>1, SUMIFS('N- Finances'!$C:$C,'N- Finances'!$A:$A,$B39), _xlfn.XLOOKUP($B39,'N- Finances'!$A:$A,'N- Finances'!$C:$C,"",0) ) -> 17568600 | J39: 18474100
B40: Optiver | I40: =IF(COUNTIF('N- Finances'!$A:$A,$B40)>1, SUMIFS('N- Finances'!$C:$C,'N- Finances'!$A:$A,$B40), _xlfn.XLOOKUP($B40,'N- Finances'!$A:$A,'N- Finances'!$C:$C,"",0) ) -> 15000000 | J40: 7500000
...

Sheet Progress- Gant
AF1: % Complete | AK1: Slow progress
G2: Legend: | I2: Plan Duration | M2: Road Block | Q2: In- rpgress | U2: Completion | AA2: Actual Start
A4: Project Name | B4: Current Phase | C4: PERCENT COMPLETE | D4: Start Date | E4: End Date | F4: 45292 | G4: 45323 | H4: 45352 | I4: 45383 | J4: 45413 | K4: 45444 | L4: 45474 | M4: 45505 | N4: 45536 | O4: 45566 | P4: 45597 | Q4: 45627 | R4: 45658 | S4: 45689 | T4: 45717 | U4: 45748 | V4: 45778 | W4: 45809 | X4: 45839 | Y4: 45870 | Z4: 45901 | AA4: 45931 | AB4: 45962 | AC4: 45992 | AD4: 46023 | AE4: 46054 | AF4: 46082 | AG4: 46113 | AH4: 46143 | AI4: 46174 | AJ4: 46204 | AK4: 46235 | AL4: 46266 | AM4: 46296 | AN4: 46327 | AO4: 46357 | AP4: 46388 | AQ4: 46419 | AR4: 46447 | AS4: 46478 | AT4: 46508 | AU4: 46539 | AV4: 46569 | AW4: 46600 | AX4: 46631 | AY4: 46661 | AZ4: 46692 | BA4: 46722
A5: Hostel 4 | C5: 1 | D5: 2023 | E5: 2025
A6: Desai Sethi School of Entreprenurship new Building | C6: 1 | D6: 2023 | E6: 45870
A7: NSAC | C7: 0.35 | D7: 2024 | E7: 46204
A8: Rahul Bajaj Technology Innovation Centre | C8: 0.1
A9: A91 Eco Hub | C9: 0.85 | E9: 2024
A10: COPT- BETIC | C10: 0.85 | D10: 2024 | E10: 46296
A11: AB1 | C11: 0.5 | D11: 2024 | E11: 46478
A12: AB2 | C12: 0.6 | D12: 2024 | E12: 46478
A13: ASB1 | C13: 0.75 | D13: 2024 | E13: 46357
A14: ASB2 | C14: 1 | D14: 2024 | E14: 46357
A15: KV | C15: 0.6 | D15: 2024 | E15: 46357
A16: Faculty Housing | C16: 0
A17: Research HUB | C17: 0.5 | D17: 2026 | E17: 46722
A18: Alumni centre | C18: 0 | D18: 2026 | E18: 2028
A19: AB3 | C19: 0.01 | D19: 2026 | E19: 46722
A20: AB4 & GESH Building | C20: 0.8 | D20: 2026 | E20: 46722
A21: Efficiency Appt | C21: 0
A22: Hostel 9 | C22: 0 | D22: 46174 | E22: 46813
A23: Hostel 6 | C23: 0 | D23: 46174 | E23: 46813
A24: Girls Hostel | C24: 0 | D24: 45182 | E24: 46277
A25: Lecture Hall Complex (OAT) | C25: 0.44
A26: ARL | C26: 0 | D26: 2026 | E26: 46600
A27: EHV | C27: 0.12
A28: MLCP | C28: 0.05
A29: Drone Centre | C29: 0 | D29: 2026 | E29: 2027
A30: Hostel 19 | C30: 0.5 | D30: 2023 | E30: 45992
A31: Hostel 11 | D31: 46357 | E31: 2028
A32: Gogri Hub | D32: 45931 | E32: 46023
A45: 45292
A46: 45323
A47: 45352
A48: 45383
A49: 45413
A50: 45444
A51: 45474
A52: 45505
A53: 45536
...

Sheet Sheet1
C2: Period Highlight: | I2: Plan Duration | M2: Road Block | Q2: In- rpgress | U2: Completion | AA2: Actual Start | AF2: % Complete | AK2: Slow progress
A3: Project Name | B3: Current Phase | C3: PERCENT COMPLETE | D3: Start Date | E3: End Date
H4: 45292 | I4: 45323 | J4: 45352 | K4: 45383 | L4: 45413 | M4: 45444 | N4: 45474 | O4: 45505 | P4: 45536 | Q4: 45566 | R4: 45597 | S4: 45627 | T4: 45658 | U4: 45689 | V4: 45717 | W4: 45748 | X4: 45778 | Y4: 45809 | Z4: 45839 | AA4: 45870 | AB4: 45901 | AC4: 45931 | AD4: 45962 | AE4: 45992 | AF4: 46023 | AG4: 46054 | AH4: 46082 | AI4: 46113 | AJ4: 46143 | AK4: 46174 | AL4: 46204 | AM4: 46235 | AN4: 46266 | AO4: 46296 | AP4: 46327 | AQ4: 46357 | AR4: 46388 | AS4: 46419 | AT4: 46447 | AU4: 46478 | AV4: 46508 | AW4: 46539 | AX4: 46569 | AY4: 46600 | AZ4: 46631 | BA4: 46661 | BB4: 46692
A5: Hostel 4 | B5: 1. Planning | C5: 0.25 | D5: =VLOOKUP(A5,'Projects Tracker'!B:F,4,1) -> 0 | E5: #VALUE!
A6: Desai Sethi School of Entreprenurship new Building | B6: 1 | C6: 1 | D6: =VLOOKUP(A6,'Projects Tracker'!B:F,4,1) -> 2026
A7: NSAC | B7: 2 | C7: 0.35 | D7: =VLOOKUP(A7,'Projects Tracker'!B:F,4,1) -> 0
A8: Rahul Bajaj Technology Innovation Centre | B8: 4 | C8: 0.1 | D8: =VLOOKUP(A8,'Projects Tracker'!B:F,4,1) -> 0
A9: A91 Eco Hub | B9: 4 | C9: 0.85 | D9: =VLOOKUP(A9,'Projects Tracker'!B:F,4,1) -> #N/A
A10: COPT- BETIC | B10: 4 | C10: 0.85 | D10: =VLOOKUP(A10,'Projects Tracker'!B:F,4,1) -> 2026 | E10: 45870
A11: AB1 | B11: 5 | C11: 0.5 | D11: =VLOOKUP(A11,'Projects Tracker'!B:F,4,1) -> 2024
A12: AB2 | B12: 5 | C12: 0.6 | D12: =VLOOKUP(A12,'Projects Tracker'!B:F,4,1) -> 2024
A13: ASB1 | B13: 5 | C13: 0.75 | D13: =VLOOKUP(A13,'Projects Tracker'!B:F,4,1) -> 2026
A14: ASB2 | B14: 6 | C14: 1 | D14: =VLOOKUP(A14,'Projects Tracker'!B:F,4,1) -> 2026
A15: KV | B15: 6 | C15: 0.6 | D15: =VLOOKUP(A15,'Projects Tracker'!B:F,4,1) -> 0
A16: Faculty Housing | B16: 9 | C16: 0 | D16: =VLOOKUP(A16,'Projects Tracker'!B:F,4,1) -> 2026
A17: Research HUB | B17: 9 | C17: 0.5 | D17: =VLOOKUP(A17,'Projects Tracker'!B:F,4,1) -> 0
A18: Alumni centre | B18: 9 | C18: 0 | D18: =VLOOKUP(A18,'Projects Tracker'!B:F,4,1) -> 2026
A19: AB3 | B19: 9 | C19: 0.01 | D19: =VLOOKUP(A19,'Projects Tracker'!B:F,4,1) -> 2026
A20: AB4 & GESH Building | B20: 10 | C20: 0.8 | D20: =VLOOKUP(A20,'Projects Tracker'!B:F,4,1) -> 2026
A21: Efficiency Appt | B21: 11 | C21: 0 | D21: =VLOOKUP(A21,'Projects Tracker'!B:F,4,1) -> 0
A22: Hostel 9 | B22: 12 | C22: 0 | D22: =VLOOKUP(A22,'Projects Tracker'!B:F,4,1) -> 0
... A30: Hostel 19 | B30: 16 | C30: 0.5 | D30: =VLOOKUP(A30,'Projects Tracker'!B:F,4,1) -> 0
A31: Hostel 11 | D31: =VLOOKUP(A31,'Projects Tracker'!B:F,4,1) -> 46357
A32: Gogri Hub | D32: =VLOOKUP(A32,'Projects Tracker'!B:F,4,1) -> 2026
A45: 45292
A46: 45323
A47: 45352
A48: 45383
A49: 45413
A50: 45444
A51: 45474
A52: 45505
A53: 45536
A54: 45566
A55: 45597
A56: 45627
... A91: 46692

Sheet N- Finances
A1: Building | B1: Centre Name | C1: FUNDS COMMITTED FOR INFRASTRUCTURE | D1: Received/Allocated to Infra | E1: Received/Allocated to Infra-After Admin | F1: Received/Allocated to Infra | G1: Interest | H1: Total Received/Allocated +Interest | I1: Total Received/Allocated +Interest (In Cr) | J1: Utilized- Transferred to Main Account | K1: Utilized- Transferred to Main Account (In Cr) | L1: Amount balance to transfer | M1: Amount balance to transfer (In Cr) | N1: To be received | O1: To be received (In Cr) | P1: WBS | Q1: Remarks | R1: COMMENTS
C2: (in Rs.)
A3: Infrastructure
A4: AB1 | B4: ADCPS | C4: 100000000 | D4: 44300000 | E4: 42971000 | F4: 4 | G4: 1191941 | H4: 44162941 | I4: 4 | J4: 24409303 | K4: 2.44 | L4: 19753638 | M4: 1.98 | N4: 55700000 | O4: 5.57 | P4: ADCPS
B5: Motilal Oswal Knowledge Center | C5: 1000000000 | D5: 340000000 | E5: 306000000 | F5: 31 | G5: ₹ - | H5: 306000000 | I5: 31 | J5: ₹ - | K5: ₹ - | L5: 306000000 | M5: 30.6 | N5: 660000000 | O5: 66 | P5: Motilal Oswal Knowledge Center
A6: AB2 | B6: CMInDS - Included SBI | C6: 487600000 | D6: 267099003 | E6: 267099003 | F6: 27 | G6: 0 | H6: 267099003 | I6: 27 | J6: 50000000 | K6: 5 | L6: 217099003 | M6: 21.71 | N6: 220500997 | O6: 22.05 | P6: CMInDS - Included SBI
B7: FedEX ALFA | C7: 75000000 | D7: ₹ - | E7: ₹ - | F7: ₹ - | G7: ₹ - | H7: ₹ - | I7: ₹ - | J7: ₹ - | K7: ₹ - | L7: ₹ - | M7: ₹ - | N7: 75000000 | O7: 7.5 | P7: FedEX ALFA
A8: Academic Block | B8: Honeywell | C8: 37500000 | D8: 37500000 | E8: 37500000 | F8: 4 | G8: ₹ - | H8: 37500000 | I8: 4 | J8: ₹ - | K8: ₹ - | L8: 37500000 | M8: 3.75 | N8: ₹ - | O8: ₹ -
A9: ASB2 | B9: KCDH | C9: 150000000 | D9: 100000000 | E9: 97000000 | F9: 10 | G9: 12946482 | H9: 109946482 | I9: 11 | J9: 733424 | K9: 0.07 | L9: 109213058 | M9: 10.92 | N9: 50000000 | O9: 5 | P9: KCDH | R9: 10.92
B10: Animal Facility | C10: 200000000 | D10: 200000000 | E10: 200000000 | F10: 20 | G10: ₹ - | H10: 200000000 | I10: 20 | J10: 103700000 | K10: 10.37 | L10: 96300000 | M10: 9.63 | N10: ₹ - | O10: ₹ - | R10: 14.3
B11: WITC | C11: 599480000 | E11: ₹ - | F11: ₹ - | H11: ₹ - | I11: ₹ - | J11: ₹ - | K11: ₹ - | L11: ₹ - | M11: ₹ - | N11: 599480000 | O11: 59.95 | P11: Wadhwani Innovation Center | R11: ₹ -
B12: Alkem | C12: 75000000 | D12: 50000000 | E12: 50000000 | F12: 5 | G12: ₹ - | H12: 50000000 | I12: ₹ - | J12: ₹ - | K12: ₹ - | L12: 50000000 | M12: 5 | N12: 25000000 | O12: 2.5 | R12: 5
A13: DSSE | B13: 2.75 million | C13: 233006082 | D13: 233006082 | E13: 226015900 | F13: 23 | G13: 0 | H13: 2.260159e+08 | I13: 23 | J13: 94731236 | K13: 9.47 | L13: 131284664 | M13: 13.13 | N13: ₹ - | O13: ₹ - | P13: 2.75 million | S13: 260 Grant | T13: 74465410 | U13: 890 lac dollor | V13: 83.669
A14: A91 Eco Hub | B14: Abhay Pandey Building | C14: 100000000 | D14: 100000000 | E14: 97000000 | F14: 10 | G14: 9050000 | H14: 106050000 | I14: 11 | J14: 107266590 | K14: 10.73 | L14: -1216590 | N14: ₹ - | O14: ₹ - | P14: Abhay Pandey Building
B15: TCA2I | C15: 60000000 | D15: 60000000 | E15: 58200000 | F15: 6 | G15: 3977290 | H15: 62177290 | I15: 6 | J15: 58610000 | K15: 5.86 | L15: 3567290 | N15: ₹ - | O15: ₹ - | P15: TCA2I
P16: TECHNOCRAFT CENTRE FOR APPLIED ARTIFICIAL INTELLIGENCE
A17: ALUMNI CENTRE | B17: Mohan Kavrie | C17: 100000000 | D17: 10000000 | E17: 9700000 | F17: 1 | G17: 0 | H17: 9700000 | I17: 1 | J17: ₹ - | K17: ₹ - | L17: 9700000 | M17: 1 | N17: 90000000 | O17: 9 | P17: Mohan Kavrie
B18: Everest | C18: 75000000 | D18: 75000000 | E18: 67500000 | F18: 7 | G18: 0 | H18: 67500000 | I18: 7 | J18: ₹ - | K18: ₹ - | L18: 67500000 | M18: 6.75 | N18: ₹ - | O18: ₹ - | P18: Everest
A19: AB4 | B19: Hub for green energy | C19: 1000000000 | D19: 199456320 | E19: 199456320 | F19: 20 | G19: 8327301 | H19: 207783621 | I19: 21 | J19: ₹ - | K19: ₹ - | L19: 207783621 | M19: 20.78 | N19: 800543680 | O19: 80.05 | P19: Hub for green energy
A20: NN315 Infra Funds | B20: Faculty Housing-B 27 | C20: 800000000 | D20: 800000000 | E20: 800000000 | F20: 80 | G20: 0 | H20: 800000000 | I20: 80 | J20: 34600000 | K20: 3.46 | L20: 765400000 | M20: 76.54 | N20: ₹ - | O20: ₹ - | P20: NN315 Infra Funds
B21: NN Main Building | C21: 120000000 | D21: 120000000 | E21: 120000000 | F21: 12 | H21: 120000000 | I21: 12 | J21: 120000000 | K21: 12 | L21: ₹ - | M21: ₹ - | N21: ₹ - | O21: ₹ - | P21: NN Main Building
B22: Rest of Fund | C22: 890000000 | N22: 890000000 | O22: 89
A23: Hostel6 | B23: Ramesh M. | C23: 50000000 | D23: 10000000 | E23: 9700000 | F23: 1 | G23: 0 | H23: 9700000 | I23: 1 | J23: ₹ - | K23: ₹ - | L23: 9700000 | M23: 0.97 | N23: 40000000 | O23: 4 | P23: Hostel6
B24: Ritesh & Nakul | C24: 900000000 | D24: ₹ - | F24: ₹ - | H24: ₹ - | I24: ₹ - | J24: ₹ - | K24: ₹ - | L24: ₹ - | M24: ₹ - | N24: 900000000 | O24: 90 | P24: Hostel 6
A25: Rahul Bajaj | B25: RBTIC | C25: 250000000 | D25: 250000000 | E25: 250000000 | F25: 25 | H25: 250000000 | I25: 25 | J25: 87505404 | K25: 8.75 | L25: 162494596 | M25: 16.25 | N25: ₹ - | O25: ₹ - | P25: Rahul Bajaj
A26: Hub | B26: Gogri Hub | C26: 75000000 | D26: 37391615 | E26: 36269867 | F26: 4 | H26: 36269867 | I26: 4 | J26: ₹ - | K26: ₹ - | L26: 36269867 | M26: 3.63 | N26: 37608385 | O26: 3.76 | P26: Gogri Hub
A27: Hostel 9 | B27: Jitendra Mohan & Sapana Samant | C27: 643293750 | D27: ₹ - | F27: ₹ - | H27: ₹ - | I27: ₹ - | J27: ₹ - | K27: ₹ - | L27: ₹ - | M27: ₹ - | N27: 643293750 | O27: 64.33 | P27: Hostel 9
A28: ICICI BETIC | C28: 142700000 | D28: 82600000 | E28: 82600000 | F28: 8 | H28: 82600000 | I28: 8 | J28: 82600000 | K28: 8.26 | L28: ₹ - | M28: ₹ - | N28: 60100000 | O28: 6.01 | P28: ICICI BETIC
C29: 8163579832 | D29: 3016353020 | E29: 2957012089 | F29: 296 | G29: 35493014 | H29: 2992505103 | I29: 294 | J29: 764155957 | K29: 76 | L29: 2228349146 | M29: 223 | N29: 5147226812 | O29: 515 | P29: ₹ - | Q29: ₹ - | R29: 30 | S29: ₹ - | T29: 74465410
D30: 301.64
O31: 545.72
A32: Naming: | C32: FUNDS COMMITTED FOR INFRASTRUCTURE | D32: Received/Allocated to Infra | E32: Received/Allocated to Infra (In Cr) | F32: Utilized- Transferred to Main Account (In Cr) | G32: To be received | H32: To be received (In Cr) | I32: Transferred To Dept.
C33: (in Rs.)
A34: BASKETBALL COURT ARINA-CLASS OF 95 | C34: 66000000 | D34: 66000000 | E34: 6.6 | F34: 1.6 | G34: ₹ - | H34: ₹ -
A35: NAMING TO CLASS OF 1993 | C35: 14000000 | D35: 14000000 | E35: 1.4 | F35: ₹ - | G35: ₹ - | H35: ₹ -
A36: SHRIDHAR SHUKLA IITB TRUST LAB | C36: 37500000 | D36: 37500000 | E36: 3.75 | F36: 3.63 | G36: ₹ - | H36: ₹ -
A37: Naming R.NO.21 VMCC PROF.VASI | C37: 9000000 | D37: 9000000 | E37: 0.9 | F37: ₹ - | G37: ₹ - | H37: ₹ -
A38: Naming corpus of HE_IITB Y1,Y2 | C38: 20000000 | D38: 10800000 | E38: 1.08 | F38: ₹ - | G38: 9200000 | H38: 0.92 | L38: 9200000
A39: INOX | C39: 7500000 | D39: 6750000 | E39: 0.68 | F39: 0.67 | G39: 750000 | H39: ₹ -
A40: Kishore Seendripu-Lecture Hall Complex 3 | C40: 416450000 | D40: 340700000 | E40: 34.07 | F40: 16.67 | G40: 75750000 | H40: 7.58
...

Sheet Financials
A1: Project Name | B1: Sub WBS | C1: Donor Name | D1: Donation Amount | E1: Estimated Cost | F1: Committed Spend | G1: Spent To Date | H1: Funding Source | I1: Currency | J1: Budget Variance | K1: Updated On
C2: Kishore Rajapurkar | D2: 3500000 | F2: 15000000 | G2: 12000000 | H2: Donor | I2: INR | J2: =D2-F2 -> -11500000 | K2: 2025-12-15
C3: Vivek Manohar Padhye | D3: 800000 | F3: 2000000 | G3: 500000 | H3: Mixed | I3: INR | J3: =D3-F3 -> -1200000 | K3: 2025-12-20
C4: Browserstack | D4: 1000000000 | J4: =D4-F4 -> 1000000000
C5: Hostel 4: MR. DILEEP BHANDARKAR | D5: 1729407 | J5: =D5-F5 -> 1729407
B6: DO/2025-H4DN | C6: Hostel 4: Pramod Chaudhari Dining Hall | D6: 175000000 | J6: =D6-F6 -> 175000000
D8: 2750000.00$

Sheet Milestones
A1: Project Code | B1: Milestone | C1: Owner | D1: Planned Date | E1: Actual Date | F1: Status | G1: Comments
A2: ACAD-001 | B2: Foundation Complete | D2: 2025-06-30 | E2: 2025-07-10 | F2: Completed | G2: 10-day delay due to rain
A3: ACAD-001 | B3: Superstructure | D3: 2025-11-30 | F3: Under Construction | G3: -
A4: NON-003 | B4: Design Approval | D4: 2026-02-15 | F4: Planning | G4: External review pending

Sheet Data- Projects
A1: MOU Name | B1: MOU Amount | C1: INR Amount | D1: MOU Signing Date | E1: MOU Duration (Year) | F1: Start Date | G1: End Date | H1: Category | I1: Sub Category | J1: Purpose | K1: Status | L1: Maker | M1: Donor | N1: Donor
A2: Campus Sustainability Fund | B2: 100000.00 $ | C2: 8,479,345.00 ₹ | D2: 2025-05-06 | E2: 4.0 | F2: 2025-05-06 | G2: 2025-05-06 | H2: Alumni | I2: Alumni General | J2: Other | K2: Active | L2: Namrata Ashok | M2: Mr. P. Pandurang Nayak | N2: Mr. P. Pandurang Nayak
A3: Coal India - Rural Technology | B3: 13816000.00 ₹ | C3: 13,816,000.00 ₹ | D3: 2025-08-13 | E3: 2.0 | F3: 2025-08-13 | G3: 2025-08-13 | H3: Corporate | I3: Corporate CSR | J3: R&D | K3: Active | L3: Josmi Joseph | M3: COAL India | N3: COAL India
A4: DL Shah Chair for Innvoation | B4: 6000000.00 ₹ | C4: 6,000,000.00 ₹ | D4: 2008-07-31 | E4: 10.0 | F4: 2008-07-31 | G4: 2008-07-31 | H4: Foundation | I4: -- | J4: Chair | K4: Active | L4: Gayatri Rupangudi | M4: D L Shah Trust for Applied Science, Technology, Arts & Philosophy | N4: D L Shah Trust for Applied Science, Technology, Arts & Philosophy
A5: Expanding Bodhitree and EvalPro for Educational Impact at IIT Bombay (Research Project). | B5: 12690310.00 ₹ | C5: 12,690,310.00 ₹ | D5: 2025-01-10 | E5: 1.0 | F5: 2024-01-10 | G5: 2024-01-10 | H5: Corporate | I5: Corporate CSR | J5: R&D | K5: Active | L5: Sreya Ganguly | M5: Tower Research Capital Markets India Limited and Asankhya Trading Private Limited | N5: Tower Research Capital Markets India Limited and Asankhya Trading Private Limited
A6: Project Evergreen : Ashutosh Joshi | B6: 40000000.00 ₹ | C6: 40,000,000.00 ₹ | D6: 2024-04-26 | E6: 5.0 | F6: 2024-04-26 | G6: 2024-04-26 | H6: Alumni | I6: Alumni General | J6: Infrastructure | K6: Active | L6: Ieshan Misri | M6: Ashutosh Joshi | N6: Ashutosh Joshi
A7: Project Evergreen : Manu Varma | B7: 120000.00 $ | C7: 10,089,534.00 ₹ | D7: 2024-10-24 | E7: 5.0 | F7: 2024-10-24 | G7: 2024-10-24 | H7: Alumni | I7: Alumni General | J7: Infrastructure | K7: Active | L7: Sagar Badhe | M7: Manu Varma | N7: Manu Varma
A8: Sahadev A Chirayath Memorial Awards | B8: 25471.00 $ | C8: 2,142,517.36 ₹ | D8: 2024-11-05 | E8: 99.0 | F8: 2024-11-05 | G8: 2024-11-05 | H8: Alumni | I8: Alumni General | J8: Award | K8: Active | L8: Rahul Talreja | M8: Group of donors represented by Prof. Chinya V Ravishankar | N8: Group of donors represented by Prof. Chinya V Ravishankar
A9: (SIL)Summer of Innovation and Leadership | B9: 7830000.00 ₹ | C9: 7,830,000.00 ₹ | D9: 2025-02-21 | E9: 3.0 | F9: 2025-05-01 | G9: 2025-05-01 | H9: Alumni | I9: Alumni Corporate Non CSR | J9: Academic Program | K9: Active | L9: Sneha Bajaj | M9: Abhay Pandey and Edunnovate Technologies | N9: Abhay Pandey and Edunnovate Technologies
A10: ABB India Foundation | B10: 10305000.00 ₹ | C10: 10,305,000.00 ₹ | D10: 2024-08-19 | E10: 0.5 | F10: 2024-07-01 | G10: 2024-07-01 | H10: Corporate | I10: Corporate CSR | J10: Lab & Equipment | K10: Active | L10: Sagar Badhe | M10: ABB India Foundation | N10: ABB India Foundation
A11: Abhay Pandey New HSS Annex | B11: 100000000.00 ₹ | C11: 100,000,000.00 ₹ | D11: 2019-01-10 | E11: 10.0 | F11: 2019-01-10 | G11: 2019-01-10 | H11: Alumni | I11: Alumni General | J11: Infrastructure | K11: Active | L11: Sakshi Thakral | M11: Abhay Pandey | N11: Abhay Pandey
A12: Abhijeet Banerjee SJMSOM Silver Medal | B12: 612000.00 ₹ | C12: 612,000.00 ₹ | D12: 2022-05-27 | E12: 10.0 | F12: 2022-05-27 | G12: 2022-05-27 | H12: Alumni | I12: Alumni General | J12: Award | K12: Active | L12: Sreenivas Chigullapalli | M12: Alumni of 2003 batch | N12: Alumni of 2003 batch
... A672: Yogen Dalal Chair in IDC | B672: 172000.00 $ | C672: 14,223,634.60 ₹ | D672: 2023-02-16 | E672: 10.0 | F672: 2023-02-16 | G672: 2023-02-16 | H672: Alumni | I672: Alumni General | J672: Chair | K672: Active | L672: Gayatri Rupangudi | M672: Dr. Yogen Dalal Chair in IDC | N672: Dr. Yogen Dalal Chair in IDC

Sheet Data- WBS
A1: MOU Name | B1: Project Name | C1: WBS No | D1: MOU Amount | E1: Project Amount | F1: Endowment | G1: Purpose | H1: Status | I1: Created Date
A2: -- | B2: Wadhwani Research Center | C2: DO/2013-WRCB | D2: -- | E2: 2500000.00 | F2: No | G2: R&D | H2: Active | I2: 2018-01-05
A3: Sahadev A Chirayath Memorial Awards | B3: Sahadev Chirayath Memorial Award | C3: DO/2024-SAHA | D3: 25471.00$ | E3: 25471.00$ | F3: Yes | G3: Award | H3: Active | I3: 2024-04-22
A4: SemiX Research & Academic projects | B4: Semiconductor Research & Academic Progra | C4: DO/2024-SRAP | D4: 1000000.00$ | E4: 1000000.00$ | F4: No | G4: R&D | H4: Active | I4: 2024-12-24
A5: CTARA Awards | B5: For Student Award In CTARA | C5: DO/2022-SACT | D5: 1500000.00₹ | E5: 1500000.00₹ | F5: Yes | G5: Award | H5: Active | I5: 2023-03-21
A6: Adani_Vakya System of Astronomy in India | B6: Vakya System of Astronomy in India | C6: DO/2024-ADAN | D6: 10500000.00₹ | E6: 10500000.00₹ | F6: No | G6: R&D | H6: Active | I6: 2024-11-21
A7: Ashank Desai Centre for Policy Studies | B7: CENTER FOR POLICY STUDIES DEVLP FUND | C7: DO/2019-CPSD | D7: 150000000.00₹ | E7: 0.00₹ | F7: Yes | G7: Infrastructure | H7: Active | I7: 2019-03-30
A8: Ashank Desai Centre for Policy Studies | B8: Ashank Desai Centre for Policy Studies Endowment | C8: DO/2021-ECPS | D8: 150000000.00₹ | E8: 100000000.00₹ | F8: Yes | G8: Other | H8: Active | I8: 2022-04-07
A9: Ashank Desai Centre for Policy Studies | B9: Ashank Desai Centre for Policy Studies | C9: DO/2021-MAJE | D9: 150000000.00₹ | E9: 50000000.00₹ | F9: No | G9: Infrastructure | H9: Active | I9: 2021-01-11
A10: Ashank Desai Centre for Policy Studies | B10: Ashank Desai Centre for Policy Studies | C10: DO/2022-ADCP | D10: 150000000.00₹ | E10: 50000000.00₹ | F10: Yes | G10: Infrastructure | H10: Active | I10: 2022-11-29
A11: Advinus Fellowship | B11: ADVINUS FELLOWSHIP IN CHEMISTRY DEPT. | C11: DO/2006-AFIC | D11: 364000.00₹ | E11: 364000.00₹ | F11: No | G11: Academic Program | H11: Active | I11: 2018-03-25
A12: Reconnect Energy Foundation - AI applications in smart energy management | B12: Create awareness of AI applications in s | C12: DO/2022-RECE | D12: 800000.00₹ | E12: 800000.00₹ | F12: No | G12: R&D | H12: Active | I12: 2023-03-31
... A1123: -- | B1123: Diamond Jubilee child nutrition centre | C1123: DO/2019-CHIN | D1123: -- | E1123: -- | F1123: -- | G1123: -- | H1123: -- | I1123: 2019-12-31
A1124: -- | C1124: DO/2019-CSRF | D1124: -- | E1124: -- | F1124: -- | G1124: -- | H1124: -- | I1124: 2020-02-20
A1125: -- | B1125: CSR Funding for Racing Team | C1125: DO/2019-CSRT | D1125: -- | E1125: -- | F1125: -- | G1125: -- | H1125: -- | I1125: 2020-02-18
A1126: -- | B1126: NEW DEAN ACR OFFICE SPACE | C1126: DO/2019-DACR | D1126: -- | E1126: -- | F1126: -- | G1126: -- | H1126: -- | I1126: 2019-07-15
A1127: -- | B1127: DJ Scholarship to the meritorious child | C1127: DO/2019-DJSS | D1127: -- | E1127: -- | F1127: -- | G1127: -- | H1127: -- | I1127: 2020-03-11
A1128: -- | B1128: DESAI SARKAR SCHOLARSHIP | C1128: DO/2019-DSSC | D1128: -- | E1128: -- | F1128: -- | G1128: -- | H1128: -- | I1128: 2020-04-08
A1129: -- | B1129: Manohar ParrikarCHAIR FOR GOOD GOVERNAN | C1129: DO/2019-ECGG | D1129: -- | E1129: -- | F1129: -- | G1129: -- | H1129: -- | I1129: 2019-04-18
A1130: -- | B1130: Empowering Tribal Communities | C1130: DO/2019-EPTC | D1130: -- | E1130: -- | F1130: -- | G1130: -- | H1130: -- | I1130: 2019-05-23
A1131: -- | B1131: Faculty and Staff LongueProject | C1131: DO/2019-FSLP | D1131: -- | E1131: -- | F1131: -- | G1131: -- | H1131: -- | I1131: 2020-02-17
A1132: -- | B1132: Hostel 3 & 6 | C1132: DO/2019-HSRP | D1132: -- | E1132: -- | F1132: -- | G1132: -- | H1132: -- | I1132: 2020-02-05
A1133: -- | B1133: Huawel Tech. India Pvt. Ltd. | C1133: DO/2019-HTIP | D1133: -- | E1133: -- | F1133: -- | G1133: -- | H1133: -- | I1133: 2019-12-19
A1134: -- | B1134: ICOS IITB FUND | C1134: DO/2019-ICOS | D1134: -- | E1134: -- | F1134: -- | G1134: -- | H1134: -- | I1134: 2019-07-05
A1135: -- | B1135: IDC GOLDEN JUBILEE | C1135: DO/2019-IDGJ | D1135: -- | E1135: -- | F1135: -- | G1135: -- | H1135: -- | I1135: 2019-03-20
A1136: -- | B1136: Industrial Engg and operation research | C1136: DO/2019-IEOR | D1136: -- | E1136: -- | F1136: -- | G1136: -- | H1136: -- | I1136: 2019-03-30
... A1338: -- | B1338: Wadhwani Innovation & Translation Centre | C1338: DO/2025-WITC | D1338: -- | E1338: -- | F1338: -- | G1338: -- | H1338: -- | I1338: 2025-10-03

Sheet Floor Plan
A1: Project Code | B1: Total Floors | C1: Floor # | D1: Function (e.g., Classrooms/Lab/Gym) | E1: Rooms/Units | F1: Approx Area (sq ft) | G1: Notes
A2: ACAD-001 | B2: 4 | C2: 1 | D2: Lecture Halls | E2: 6 | F2: 12000 | G2: Includes reading room
A3: ACAD-001 | B3: 4 | C3: 2 | D3: Labs | E3: 8 | F3: 15000 | G3: Wet + Dry labs
A4: ACAD-001 | B4: 4 | C4: 3 | D4: Faculty Offices | E4: 20 | F4: 9000
A5: ACAD-001 | B5: 4 | C5: 4 | D5: Library | E5: 1 | F5: 9000 | G5: Quiet zones
A6: NON-003 | B6: 3 | C6: 1 | D6: Gym | E6: 1 | F6: 8000 | G6: With music room adjacent
A7: DO/2025-HCT9
A8: DO/2025-HCT4

Sheet Risks & Issues
A1: Project Code | B1: Risk/Issue | C1: Type | D1: Probability | E1: Impact | F1: Owner | G1: Mitigation | H1: Status | I1: Target Date
A2: ACAD-001 | B2: Permit delay | C2: Risk | D2: High | E2: Medium | F2: S. Gupta | G2: Escalate with authority | H2: Open | I2: 2025-08-15
A3: NON-003 | B3: Budget shortfall | C3: Risk | D3: Medium | E3: High | F3: N. Mathur | G3: Seek additional donor funding | H3: Open | I3: 2026-05-01

Sheet Contacts & Approvals
A1: Project Code | B1: Role | C1: Name | D1: Email | E1: Phone | F1: Approval Required | G1: Approval Status | H1: Approval Date
A2: ACAD-001 | B2: Architect | C2: A. Desai | D2: architect@firm.in | E2: +91-90000-11111 | F2: Building Permit | G2: Approved | H2: 2025-05-12
A3: NON-003 | B3: Contractor | C3: BuildCo Pvt Ltd | D3: pm@buildco.in | E3: +91-98888-22222 | F3: Environmental | G3: Pending

Sheet Document Links
A1: Project Code | B1: Doc Type | C1: Description | D1: Link | E1: Uploaded On
A2: ACAD-001 | B2: GFC Drawing | C2: Structural GFC set v3 | D2: https://sharepoint.example/docs/gfc-v3 | E2: 2025-10-20
A3: ACAD-001 | B3: Render | C3: Exterior render set | D3: https://sharepoint.example/docs/render | E3: 2025-09-12
A4: NON-003 | B4: Permit | C4: Municipal approval | D4: https://drive.example/docs/permit | E4: 2026-03-01

Sheet Rough
A1: Rahul Bajaj … | B1: 208460 | C1: 70
A2: Desai Sethi School of Entreprenurship new Building | B2: 134504 | C2: 60
A3: A91 Eco Hub | B3: 54235 | C3: 90
A4: New Student Activity Centre | B4: 56903 | C4: 45
A6: Lakhamraju Buildin and Motilal Oswal Centre | B6: 386212 | C6: 190
A7: AB3& GESH Building | B7: 299024 | C7: 258
A8: ASB1 | B8: 353285 | C8: 218
A9: Wadhwani Hub | B9: 115971 | C9: 90
A10: Mohan Kavrie Alumni centre | B10: 155454 | C10: 110
A11: Faculty Housing | B11: 455452 | C11: 100
A12: COPT | B12: 156498 | C12: 99
A13: Efficiency Appt | B13: 499690 | C13: 226
... A21: Girls Hostel | B21: 51433 | C21: 160
A22: (Old Staff Hostel)

Sheet Sheet3
A1: Hostel 4 | B1: =VLOOKUP(A1,'Projects Tracker'!B:G,4,1) -> 0
A2: Desai Sethi School of Entreprenurship new Building
A3: NSAC
A4: Rahul Bajaj Technology Innovation Centre
A5: A91 Eco Hub
A6: COPT- BETIC
A7: AB1
A8: AB2
A9: ASB1
A10: ASB2
A11: KV
A12: Faculty Housing
A13: Research HUB
... A28: Gogri Hub

Sheet Sheet2
A1: Status | B1: Building | C1: Area Sqft | D1: Beds | E1: Estimimated Cost (cr) | F1: Donor Funds
B2: Hostel5 | D2: 250 | E2: 5.5 | F2: 5.5
A3: Completed | B3: Hostel no.4 | C3: 398430.97 | D3: 1206 | E3: 160 | F3: 20 | H3: =E3*10^7/C3 -> 4015.7521
B4: Evergreen 7, 8, 21 | C4: 438546.24 | D4: 1127 | E4: 200 | F4: 200 | H4: =E4*10^7/C4 -> 4560.5225 | J4: =SUM(F2:F5)/SUM(E2:E5) -> 0.48442535
B5: Hostel no 19 | C5: 360791.52 | D5: 1051 | E5: 100 | F5: 0
A7: Design getting finalized | B7: Hostel no.6 | C7: 423025.2 | D7: 850 | E7: 180 | F7: 105
B8: Hostel no.9 | C8: 322920 | D8: 850 | E8: 165 | F8: =7*9 -> 63 | J8: =SUM(F7:F11)/SUM(E7:E11) -> 0.27722772
A10: Future Planning | B10: Hostel no.11 | C10: 51432.8 | D10: 1000 | E10: 160 | F10: 0
B11: Hostel 12E&14D | C11: 193680 | D11: 503 | E11: 101 | F11: 0
C13: =SUM(C3:C12)/10^6 -> 2.1888267 | E13: =SUM(E2:E12) -> 1071.5 | F13: =SUM(F2:F12) -> 393.5
A21: Status | B21: Building | C21: Area Sqft | D21: Estimated Cost (cr) | F21: Donor Funds
A22: Completed | B22: Rahul Bajaj Technology Innovation Centre | C22: 208460.36 | D22: 70 | E22: Next to VMCC | F22: 25
B23: Desai Sethi School of Entreprenurship new Building | C23: 134503.71 | D23: 60 | E23: Main building behind | F23: 23.3
B24: A91 Eco Hub | C24: 54234.952 | D24: 90 | E24: BSBE behing | F24: 16
B25: New Student Activity Centre | C25: =5318*10.7 -> 56902.6 | D25: 45 | E25: Opp new DSSE building | F25: 0
A27: Under Construction/Design | B27: Lakhamraju Buildin and Motilal Oswal Centre | C27: 386212.32 | D27: 190 | E27: RBTIC ke saamne | F27: 166.62
B28: AB3& GESH Building | C28: 299023.92 | D28: 258 | E28: RBTIC ke saamne | F28: 100
B29: ASB1 | C29: 353285.24 | D29: 218 | E29: on the map | F29: 0
B30: Wadhwani Hub | C30: 115971.34 | D30: 90 | E30: on the map | F30: 102.45
B31: Mohan Kavrie Alumni centre | C31: 155454 | D31: 110 | E31: Hostel 10 ke opp. Ground | F31: 32.5
B32: Faculty Housing | C32: =159608*2 -> 319216 | D32: 160 | F32: 80
B33: COPT | C33: 156497.8 | D33: 99 | E33: Next to reseatch Park | F33: 15
B34: Efficiency Appt | C34: =46700*10.7 -> 499690 | D34: 226 | F34: 0
A36: Future Planning | B36: ARL | C36: 112742.14 | D36: 170 | F36: 0
B37: Research HUB | C37: =15000*10.7 -> 160500 | D37: 141 | F37: 0
B38: EHV | C38: =3600*10.7 -> 38520 | D38: 127 | F38: 0
B39: Lecture Hall Complex/OAT | C39: =12140*10.7 -> 129898 | D39: 120 | F39: 0
B40: MLCP | C40: =20000*10.76 -> 215200 | D40: 140 | F40: 0
B41: Drone Centre | C41: =3000*10.76 -> 32280 | D41: 97 | F41: 0
B42: Naming Funds | F42: 100
B43: Gogri | C43: 10000 | D43: 7.5 | F43: 7.5
B44: NN315 Infra | C44: =100*10^7/7500 -> 133333.33 | D44: 100 | F44: =189-80 -> 109
C46: =SUM(C22:C44)/10^6 -> 3.5719257 | D46: =SUM(D22:D44) -> 2518.5 | F46: =SUM(F22:F44) -> 777.37
B49: Total Cost | C49: =D46+[1]Hostel!E33 -> 2518.5
B50: Total Donor Funds | C50: =F46+[1]Hostel!F33 -> 777.37
E52: Cost | F52: Donor Funds
B53: Total Expansion Plan | C53: =C46+[1]Hostel!C33 -> 3.5719257
B54: Total Built so far | C54: =SUM(C22:C25)+SUM([1]Hostel!C23:C25) -> 454101.63 | E54: =SUM(D22:D25)+SUM([1]Hostel!E23:E25) -> 265 | F54: =SUM(F22:F25)+SUM([1]Hostel!F23:F25) -> 64.3 | G54: =F54/E54 -> 0.24264151
B55: Total under construction/design | C55: =SUM(C27:C34)+SUM([1]Hostel!C27:C28) -> 2285350.6 | E55: =SUM(D27:D34)+SUM([1]Hostel!E27:E28) -> 1351 | F55: =SUM(F27:F34)+SUM([1]Hostel!F27:F28)+F42+F43+F44 -> 713.07 | G55: =F55/E55 -> 0.52780903
B56: Future Planning | C56: =SUM(C36:C42)+SUM([1]Hostel!C30:C31) -> 689140.14 | E56: =SUM(D36:D42)+SUM([1]Hostel!E30:E31) -> 795 | F56: 0 | G56: =F56/E56 -> 0
...
